Workbook

Sheet CCS data
A1: Technology | B1: Dispachable | C1: Nominal investment (*total) [MEUR/MW_e] | D1: Nominal investment (*total) [MEUR/MW_e/m] | E1: Variable O&M (*total) [EUR/MWh_e] | F1: Fixed O&M (*total) [EUR/MW_e/y] | G1: Fixed O&M (*total) [EUR/MW_e/y/m] | H1: Year
A2: CCS | B2: 1 | C2: =plants!P6120 -> 0.090291697 | D2: =plants!O6120 -> 3.7112763e-07 | E2: =plants!H6120 -> 6.1551039 | F2: =plants!I6120 -> 78015.04 | G2: =plants!J6120 -> 0.012265588 | H2: 2030

Sheet plants
A1: name | B1: company | C1: street | D1: postcode | E1: city | F1: country | G1: capacity | H1: energy_source | I1: technology | K1: chp | L1: commissioned | M1: type | N1: lat | P1: lon | Q1: eic_code | R1: energy_source_level_1 | S1: energy_source_level_2 | T1: energy_source_level_3 | U1: additional_info | V1: comment | W1: source
A2: Marcinelle Energie (Carsid) | B2: DIRECT ENERGIE | F2: BE | G2: 413 | H2: Natural gas | I2: Combined cycle | N2: 50.41396 | P2: 4.40645 | Q2: 22WMARCIN000179H | R2: Fossil fuels | S2: Natural gas | W2: https://www.elia.be/en/grid-data/power-generation/generating-facilities#
A3: Aalst Syral GT | B3: Electrabel | F3: BE | G3: 43 | H3: Natural gas | I3: Gas turbine | K3: Yes | M3: CHP/IPP | R3: Fossil fuels | S3: Natural gas | W3: https://www.elia.be/en/grid-data/power-generation/generating-facilities#
A4: Aalst Syral ST | B4: Electrabel | F4: BE | G4: 5 | H4: Natural gas | I4: Steam turbine | K4: Yes | M4: CHP/IPP | R4: Fossil fuels | S4: Natural gas | W4: https://www.elia.be/en/grid-data/power-generation/generating-facilities#
A5: AALTER TJ | B5: Electrabel | F5: BE | G5: 18 | H5: Oil | I5: Gas turbine | R5: Fossil fuels | S5: Oil | W5: https://www.elia.be/en/grid-data/power-generation/generating-facilities#
A6: Amercoeur 1 R TGV | B6: Electrabel | F6: BE | G6: 451 | H6: Natural gas | I6: Combined cycle | N6: 50.43004 | P6: 4.39518 | Q6: 22WAMERCO000010Y | R6: Fossil fuels | S6: Natural gas | W6: https://www.elia.be/en/grid-data/power-generation/generating-facilities#
A7: AWIRS 4 | B7: Electrabel | F7: BE | G7: 95 | H7: Biomass and biogas | I7: Steam turbine | N7: 50.58508 | P7: 5.41886 | R7: Renewable energy | S7: Bioenergy | T7: Biomass and biogas | W7: https://www.elia.be/en/grid-data/power-generation/generating-facilities#
A8: BEERSE TJ | B8: Electrabel | F8: BE | G8: 32 | H8: Oil | I8: Gas turbine | R8: Fossil fuels | S8: Oil | W8: https://www.elia.be/en/grid-data/power-generation/generating-facilities#
A9: Beveren Ineos Phenolchemie | B9: Electrabel | F9: BE | G9: 23.8 | H9: Natural gas | K9: Yes | M9: CHP/IPP | R9: Fossil fuels | S9: Natural gas | W9: https://www.elia.be/en/grid-data/power-generation/generating-facilities#
A10: BUTGENBACH | B10: Electrabel | F10: BE | G10: 1.8 | H10: Hydro | R10: Renewable energy | S10: Hydro | W10: https://www.elia.be/en/grid-data/power-generation/generating-facilities#
A11: CIERREUX TJ | B11: Electrabel | F11: BE | G11: 18 | H11: Oil | I11: Gas turbine | R11: Fossil fuels | S11: Oil | W11: https://www.elia.be/en/grid-data/power-generation/generating-facilities#
A12: COO I T | B12: Electrabel | F12: BE | G12: 474 | H12: Hydro | N12: 50.38254 | P12: 5.84414 | Q12: 22WCOOXIX000067T | R12: Renewable energy | S12: Hydro | V12: Basin | W12: https://www.elia.be/en/grid-data/power-generation/generating-facilities#
A13: COO II T | B13: Electrabel | F13: BE | G13: 690 | H13: Hydro | N13: 50.38254 | P13: 5.84414 | Q13: 22WCOOXII000070C | R13: Renewable energy | S13: Hydro | V13: Basin | W13: https://www.elia.be/en/grid-data/power-generation/generating-facilities#
A14: DOEL 1 | B14: Electrabel | F14: BE | G14: 445 | H14: Nuclear | I14: Steam turbine | N14: 51.32481 | P14: 4.25889 | Q14: 22WDOELX1000076X | R14: Nuclear | W14: https://www.elia.be/en/grid-data/power-generation/generating-facilities#
A15: DOEL 2 | B15: Electrabel | F15: BE | G15: 433 | H15: Nuclear | I15: Steam turbine | N15: 51.32481 | P15: 4.25889 | Q15: 22WDOELX2000077N | R15: Nuclear | W15: https://www.elia.be/en/grid-data/power-generation/generating-facilities#
A16: DOEL 3 | B16: Electrabel | F16: BE | G16: 1006 | H16: Nuclear | I16: Steam turbine | N16: 51.32481 | P16: 4.25889 | Q16: 22WDOELX3000078D | R16: Nuclear | W16: https://www.elia.be/en/grid-data/power-generation/generating-facilities#
A17: DOEL 4 | B17: Electrabel | F17: BE | G17: 1039 | H17: Nuclear | I17: Steam turbine | N17: 51.32481 | P17: 4.25889 | Q17: 22WDOELX40000793 | R17: Nuclear | W17: https://www.elia.be/en/grid-data/power-generation/generating-facilities#
A18: DROGENBOS DM 51 | B18: Electrabel | F18: BE | G18: 2.5 | H18: Oil | N18: 50.80244 | P18: 4.30072 | R18: Fossil fuels | S18: Oil | V18: NoMetering | W18: https://www.elia.be/en/grid-data/power-generation/generating-facilities#
A19: DROGENBOS DM 52 | B19: Electrabel | F19: BE | G19: 2.5 | H19: Oil | N19: 50.80244 | P19: 4.30072 | R19: Fossil fuels | S19: Oil | V19: NoMetering | W19: https://www.elia.be/en/grid-data/power-generation/generating-facilities#
A20: DROGENBOS GT1 | B20: Electrabel | F20: BE | G20: 150 | H20: Natural gas | I20: Gas turbine | R20: Fossil fuels | S20: Natural gas | W20: https://www.elia.be/en/grid-data/power-generation/generating-facilities#
A21: DROGENBOS GT2 | B21: Electrabel | F21: BE | G21: 150 | H21: Natural gas | I21: Gas turbine | R21: Fossil fuels | S21: Natural gas | W21: https://www.elia.be/en/grid-data/power-generation/generating-facilities#
A22: DROGENBOS ST | B22: Electrabel | F22: BE | G22: 160 | H22: Natural gas | I22: Steam turbine | R22: Fossil fuels | S22: Natural gas | W22: https://www.elia.be/en/grid-data/power-generation/generating-facilities#
A23: HERDERSBRUG STEG | B23: Electrabel | F23: BE | G23: 465 | H23: Natural gas | I23: Combined cycle | N23: 51.26307 | P23: 3.21121 | Q23: 22WHERDER0001288 | R23: Fossil fuels | S23: Natural gas | W23: https://www.elia.be/en/grid-data/power-generation/generating-facilities#
A24: IXELLES TJ | B24: Electrabel | F24: BE | G24: 18 | H24: Oil | I24: Gas turbine | R24: Fossil fuels | S24: Oil | W24: https://www.elia.be/en/grid-data/power-generation/generating-facilities#
A25: La Vierre | B25: Electrabel | F25: BE | G25: 1.9 | H25: Hydro | R25: Renewable energy | S25: Hydro | W25: https://www.elia.be/en/grid-data/power-generation/generating-facilities#
A26: Lanaken Sappi | B26: Electrabel | F26: BE | G26: 43 | H26: Natural gas | K26: Yes | M26: CHP/IPP | R26: Fossil fuels | S26: Natural gas | W26: https://www.elia.be/en/grid-data/power-generation/generating-facilities#
A27: LANGERBRUGGE STORA ST 1 | B27: Electrabel | F27: BE | G27: 11 | H27: Non-renewable waste | I27: Steam turbine | K27: Yes | M27: CHP/IPP | R27: Fossil fuels | S27: Non-renewable waste | W27: https://www.elia.be/en/grid-data/power-generation/generating-facilities#
A28: LANGERBRUGGE STORA ST 2 | B28: Electrabel | F28: BE | G28: 44.7 | H28: Non-renewable waste | I28: Steam turbine | K28: Yes | M28: CHP/IPP | R28: Fossil fuels | S28: Non-renewable waste | W28: https://www.elia.be/en/grid-data/power-generation/generating-facilities#
A29: Lillo Degussa GT1 | B29: Electrabel | F29: BE | G29: 43 | H29: Natural gas | I29: Gas turbine | K29: Yes | M29: CHP/IPP | R29: Fossil fuels | S29: Natural gas | W29: https://www.elia.be/en/grid-data/power-generation/generating-facilities#
A30: Lillo Degussa GT2 | B30: Electrabel | F30: BE | G30: 32 | H30: Natural gas | I30: Gas turbine | K30: Yes | M30: CHP/IPP | R30: Fossil fuels | S30: Natural gas | W30: https://www.elia.be/en/grid-data/power-generation/generating-facilities#
A31: Lillo Degussa ST | B31: Electrabel | F31: BE | G31: 10 | H31: Natural gas | I31: Steam turbine | K31: Yes | M31: CHP/IPP | R31: Fossil fuels | S31: Natural gas | W31: https://www.elia.be/en/grid-data/power-generation/generating-facilities#
A32: Noordschote TJ | B32: Electrabel | F32: BE | G32: 18 | H32: Oil | I32: Gas turbine | R32: Fossil fuels | S32: Oil | W32: https://www.elia.be/en/grid-data/power-generation/generating-facilities#
A33: Oorderen Bayer | B33: Electrabel | F33: BE | G33: 43 | H33: Natural gas | K33: Yes | M33: CHP/IPP | R33: Fossil fuels | S33: Natural gas | W33: https://www.elia.be/en/grid-data/power-generation/generating-facilities#
A34: Oud-Lillo Monsanto | B34: Electrabel | F34: BE | G34: 43 | H34: Natural gas | K34: Yes | M34: CHP/IPP | R34: Fossil fuels | S34: Natural gas | W34: https://www.elia.be/en/grid-data/power-generation/generating-facilities#
A35: RODENHUIZE 4 | B35: Electrabel | F35: BE | G35: 268 | H35: Biomass and biogas | I35: Steam turbine | N35: 51.13421 | P35: 3.77598 | Q35: 22WRODENH000213L | R35: Renewable energy | S35: Bioenergy | T35: Biomass and biogas | W35: https://www.elia.be/en/grid-data/power-generation/generating-facilities#
A36: SAINT-GHISLAIN STEG | B36: Electrabel | F36: BE | G36: 350 | H36: Natural gas | I36: Combined cycle | N36: 50.47167 | P36: 3.82521 | Q36: 22WSAINT-000221B | R36: Fossil fuels | S36: Natural gas | W36: https://www.elia.be/en/grid-data/power-generation/generating-facilities#
A37: Schaerbeek Siomab ST1 | B37: Electrabel | F37: BE | G37: 15 | H37: Non-renewable waste | I37: Steam turbine | R37: Fossil fuels | S37: Non-renewable waste | W37: https://www.elia.be/en/grid-data/power-generation/generating-facilities#
A38: Schaerbeek Siomab ST2 | B38: Electrabel | F38: BE | G38: 15 | H38: Non-renewable waste | I38: Steam turbine | R38: Fossil fuels | S38: Non-renewable waste | W38: https://www.elia.be/en/grid-data/power-generation/generating-facilities#
A39: Schaerbeek Siomab ST3 | B39: Electrabel | F39: BE | G39: 15 | H39: Non-renewable waste | I39: Steam turbine | R39: Fossil fuels | S39: Non-renewable waste | W39: https://www.elia.be/en/grid-data/power-generation/generating-facilities#
A40: Scheldelaan Exxonmobil | B40: Electrabel | F40: BE | G40: 140 | H40: Natural gas | K40: Yes | M40: CHP/IPP | Q40: 22WSCHELD0002261 | R40: Fossil fuels | S40: Natural gas | W40: https://www.elia.be/en/grid-data/power-generation/generating-facilities#
...

Sheet Final table
G5: Final Table
D21: Questuions:
D22: Are these technologies covering denmarks current state of none renewables?
D23: Or should we assume that these sources are sufficient?
D24: How do we derive marginal cost from fixed and variable operating costs? | G24: > use variable cost | H24: Fixed = annual mainteinance
D25: Need marginal fuel prices?
D26: Add co2 emisisons? How would we include this in the model if we want to track co2 emission?
D27: We can also include start up time, but it might not be relevant in our context?
D28: How to hanlde mixed fossil fuels?
